Workbook
Name Slicer_Country: #N/A

Sheet Data
C1: Employee Data
C5: Name | D5: Gender | E5: Department | F5: Age | G5: Date Joined | H5: Salary | I5: Rating
C6: Lindy Guillet | D6: Male | E6: Sales | F6: 22 | G6: 44446 | H6: 112780 | I6: Above average
C7: Ambros Murthwaite | D7: Male | E7: Procurement | F7: 46 | G7: 44758 | H7: 70610 | I7: Average
C8: Tatum Hush | D8: Female | E8: Sales | F8: 28 | G8: 44357 | H8: 53240 | I8: Average
C9: Benny Karolovsky | E9: Finance | F9: 37 | G9: 44146 | H9: 115440 | I9: Poor
C10: Hoyt D'Alesco | D10: Male | E10: Sales | F10: 32 | G10: 44465 | H10: 53540 | I10: Average
C11: Halimeda Kuscha | D11: Female | E11: Procurement | F11: 30 | G11: 44861 | H11: 112570 | I11: Average
C12: Erin Androsik | D12: Male | E12: Procurement | F12: 33 | G12: 44701 | H12: 48530 | I12: Above average
C13: Vic Radolf | D13: Female | E13: Website | F13: 24 | G13: 44148 | H13: 62780 | I13: Average
C14: William Reeveley | D14: Male | E14: Website | F14: 33 | G14: 44509 | H14: 53870 | I14: Average
C15: Ewart Laphorn | D15: Female | E15: HR | F15: 27 | G15: 44122 | H15: 119110 | I15: Average
C16: Bev Lashley | D16: Male | E16: Website | F16: 29 | G16: 44180 | H16: 112110 | I16: Poor
C17: Kath Bletsoe | D17: Male | E17: Sales | F17: 25 | G17: 44383 | H17: 65700 | I17: Average
C18: Murry Dryburgh | D18: Male | E18: Website | F18: 37 | G18: 44701 | H18: 69070 | I18: Average
C19: Kaine Padly | D19: Male | E19: Website | F19: 20 | G19: 44459 | H19: 107700 | I19: Average
C20: Kassi Jonson | D20: Female | E20: Website | F20: 32 | G20: 44354 | H20: 43840 | I20: Above average
C21: Simon Kembery | D21: Male | E21: Procurement | F21: 40 | G21: 44263 | H21: 99750 | I21: Average
... C29: Esmaria Denecamp | D29: Male | E29: Finance | F29: 27 | G29: 44567 | H29: 48980 | I29: Average
C30: Curtice Advani | E30: Finance | F30: 30 | G30: 44597 | H30: 64000 | I30: Average
C31: Barr Faughny | D31: Female | E31: Procurement | F31: 42 | G31: 44779 | H31: 75000 | I31: Exceptional
C32: Merrilee Plenty | D32: Female | E32: Website | F32: 40 | G32: 44337 | H32: 87620 | I32: Average
C33: Niall Selesnick | D33: Female | E33: Website | F33: 29 | G33: 44023 | H33: 34980 | I33: Average
C34: Beverie Moffet | D34: Female | E34: Finance | F34: 28 | G34: 44185 | H34: 75970 | I34: Average
C35: Jehu Rudeforth | D35: Female | E35: Finance | F35: 34 | G35: 44612 | H35: 60130 | I35: Average
C36: Camilla Castle | D36: Female | E36: Website | F36: 33 | G36: 44374 | H36: 75480 | I36: Very poor
C37: Roddy Speechley | D37: Male | E37: Procurement | F37: 33 | G37: 44164 | H37: 115920 | I37: Average
C38: Gray Seamon | D38: Female | E38: Sales | F38: 36 | G38: 44494 | H38: 78540 | I38: Average
C39: Madelene Upcott | D39: Male | E39: Procurement | F39: 25 | G39: 44726 | H39: 109190 | I39: Above average
C40: Violante Courtonne | D40: Female | E40: Sales | F40: 34 | G40: 44721 | H40: 49630 | I40: Poor
C41: Bernie Gorges | D41: Female | E41: Procurement | F41: 28 | G41: 44630 | H41: 99970 | I41: Average
C42: Torrance Collier | D42: Female | E42: Website | F42: 33 | G42: 44190 | H42: 96140 | I42: Average
... C67: Wilone O'Kielt | D67: Female | E67: Website | F67: 43 | G67: 45045 | H67: 114870 | I67: Average
C68: Madge McCloughen | E68: Website | F68: 32 | G68: 44774 | H68: 91310 | I68: Average
C69: Janene Hairsine | D69: Female | E69: Procurement | F69: 28 | G69: 44486 | H69: 104770 | I69: Average
C70: Alta Kaszper | D70: Male | E70: Sales | F70: 27 | G70: 44134 | H70: 54970 | I70: Average
C71: Dennison Crosswaite | E71: Website | F71: 26 | G71: 44271 | H71: 90700 | I71: Above average
C72: Oran Buxcy | D72: Female | E72: Sales | F72: 38 | G72: 44329 | H72: 56870 | I72: Above average
C73: Hinda Label | D73: Female | E73: Sales | F73: 25 | G73: 44205 | H73: 92700 | I73: Average
C74: Marney O'Breen | D74: Female | E74: Finance | F74: 21 | G74: 44317 | H74: 65920 | I74: Average
...

Sheet India Staff
B2: Name | C2: Gender | D2: Age | E2: Rating | F2: Date Joined | G2: Department | H2: Salary
B3: Deepali Charan | C3: Male | D3: 20 | E3: Average | F3: 44122 | G3: Website | H3: 112650
B4: Yagna Sujeev | C4: Female | D4: 32 | E4: Above average | F4: 44293 | G4: Website | H4: 43840
B5: Satyendra Venkatadri | C5: Male | D5: 31 | E5: Average | F5: 44663 | G5: Procurement | H5: 103550
B6: Madhavdas Buhpathi | C6: Female | D6: 32 | E6: Average | F6: 44339 | G6: HR | H6: 45510
B7: Sahila Chandrasekhar | D7: 37 | E7: Poor | F7: 44085 | G7: Finance | H7: 115440
B8: Mirium Seemantini Shivakumar | C8: Female | D8: 38 | E8: Above average | F8: 44268 | G8: Sales | H8: 56870
B9: Purnendu Vijayarangan | C9: Female | D9: 25 | E9: Average | F9: 44144 | G9: Sales | H9: 92700
B10: Rukma Vinita | D10: 32 | E10: Average | F10: 44713 | G10: Website | H10: 91310
B11: Yauvani Tarpa | C11: Male | D11: 33 | E11: Average | F11: 44324 | G11: Sales | H11: 74550
B12: Damayanti Thangavadivelu | C12: Male | D12: 25 | E12: Above average | F12: 44665 | G12: Procurement | H12: 109190
B13: Manjusri Ruchi | C13: Female | D13: 40 | E13: Average | F13: 44320 | G13: Website | H13: 104410
B14: Mithil Nadkarni | C14: Male | D14: 30 | E14: Average | F14: 44544 | G14: Finance | H14: 96800
B15: Ardhendu Abhichandra Jayakar | C15: Male | D15: 28 | E15: Above average | F15: 43980 | G15: Finance | H15: 48170
B16: Akbar Sorabhjee | C16: Male | D16: 21 | E16: Average | F16: 44042 | G16: Procurement | H16: 37920
B17: Bandhula Sathyanna | C17: Male | D17: 34 | E17: Average | F17: 44642 | G17: Procurement | H17: 112650
B18: Daruka Ghazali | C18: Female | D18: 34 | E18: Poor | F18: 44660 | G18: Sales | H18: 49630
B19: Heer Pennathur | C19: Male | D19: 36 | E19: Average | F19: 43958 | G19: Website | H19: 118840
B20: Shekhar Eswara | C20: Male | D20: 30 | E20: Average | F20: 44789 | G20: Website | H20: 69710
B21: Udyan Lanka | C21: Male | D21: 20 | E21: Average | F21: 44683 | G21: Procurement | H21: 79570
B22: Shreela Ramasubraman | C22: Female | D22: 22 | E22: Above average | F22: 44388 | G22: Procurement | H22: 76900
... B53: Indu Varada Sumedh | C53: Female | D53: 28 | E53: Average | F53: 44124 | G53: Finance | H53: 75970
B54: Karuna Pashupathy | D54: 27 | E54: Above average | F54: 44212 | G54: Website | H54: 90700
B55: Mardav Ramaswami | C55: Male | D55: 30 | E55: Average | F55: 44607 | G55: Procurement | H55: 60570
B56: Sarayu Ragunathan | C56: Male | D56: 33 | E56: Average | F56: 44103 | G56: Procurement | H56: 115920
B57: Kevalkumar Solanki | C57: Female | D57: 33 | E57: Average | F57: 44006 | G57: Finance | H57: 65360
B58: Upendra Swati | D58: 30 | E58: Average | F58: 44535 | G58: Finance | H58: 64000
B59: Deepit Ranjana | C59: Female | D59: 34 | E59: Average | F59: 44383 | G59: Finance | H59: 92450
B60: Amal Nimesh | C60: Male | D60: 31 | E60: Average | F60: 44450 | G60: Website | H60: 48950
B61: Kunja Prashanta Vibha | C61: Female | D61: 27 | E61: Average | F61: 44625 | G61: Website | H61: 83750
B62: Godavari Veena | C62: Female | D62: 40 | E62: Average | F62: 44276 | G62: Website | H62: 87620
B63: Devasree Fullara Saurin | C63: Female | D63: 20 | E63: Poor | F63: 44476 | G63: Sales | H63: 68900
B64: Geena Raghavanpillai | C64: Male | D64: 32 | E64: Average | F64: 44403 | G64: Sales | H64: 53540
B65: Rupak Mehra | C65: Male | D65: 28 | E65: Very poor | F65: 44758 | G65: Sales | H65: 43510
B66: Sawini Chandan | C66: Female | D66: 38 | E66: Exceptional | F66: 44316 | G66: Sales | H66: 109160
B67: Baruna Ogale | C67: Male | D67: 40 | E67: Average | F67: 44204 | G67: Procurement | H67: 99750
B68: Jagajeet Viraj | C68: Female | D68: 31 | E68: Average | F68: 44084 | G68: Website | H68: 41980
B69: Kulbhushan Moorthy | C69: Male | D69: 36 | E69: Average | F69: 44272 | G69: Finance | H69: 71380
B70: Ilesh Dasgupta | C70: Male | D70: 27 | E70: Very poor | F70: 44547 | G70: Procurement | H70: 113280
... B98: Madhavdas Buhpathi | C98: Female | D98: 32 | E98: Average | F98: 44339 | G98: HR | H98: 45510
...

Sheet ALL Staff
A1: Name | B1: Gender | C1: Age | D1: Rating | E1: Date Joined | F1: Department | G1: Salary | H1: Country | I1: Tenure | J1: Bonus | K1: Rating as Number
A2: Shubhra Potla | B2: Female | C2: 21 | D2: Average | E2: 44619 | F2: Website | G2: 33920 | H2: India | I2: =(TODAY()-staff[[#This Row],[Date Joined]])/365 -> 4.1452055 | J2: =ROUNDUP(IF(staff[[#This Row],[Tenure]]>3,3%,2%)*staff[[#This Row],[Salary]],0) -> 1018 | K2: =_xlfn.XLOOKUP(staff[[#This Row],[Rating]],Analysis!$B$2:$B$6,Analysis!$C$2:$C$6) -> 3
A3: Gretchen Callow | B3: Female | C3: 21 | D3: Average | E3: 44678 | F3: Website | G3: 33920 | H3: NZ | I3: =(TODAY()-staff[[#This Row],[Date Joined]])/365 -> 3.9835616 | J3: =ROUNDUP(IF(staff[[#This Row],[Tenure]]>3,3%,2%)*staff[[#This Row],[Salary]],0) -> 1018 | K3: =_xlfn.XLOOKUP(staff[[#This Row],[Rating]],Analysis!$B$2:$B$6,Analysis!$C$2:$C$6) -> 3 | M3: 1 | N3: Count of employees | O3: =COUNTA(staff[Name]) -> 183
A4: Suchira Bhanupriya Tapti | B4: Female | C4: 29 | D4: Average | E4: 43962 | F4: Website | G4: 34980 | H4: India | I4: =(TODAY()-staff[[#This Row],[Date Joined]])/365 -> 5.9452055 | J4: =ROUNDUP(IF(staff[[#This Row],[Tenure]]>3,3%,2%)*staff[[#This Row],[Salary]],0) -> 1050 | K4: =_xlfn.XLOOKUP(staff[[#This Row],[Rating]],Analysis!$B$2:$B$6,Analysis!$C$2:$C$6) -> 3 | N4: Average salary | O4: =AVERAGE(staff[Salary]) -> 77173.716 | P4: Median | Q4: =MEDIAN(staff[[#All],[Salary]]) -> 75000
A5: Niall Selesnick | B5: Female | C5: 29 | D5: Average | E5: 44023 | F5: Website | G5: 34980 | H5: NZ | I5: =(TODAY()-staff[[#This Row],[Date Joined]])/365 -> 5.7780822 | J5: =ROUNDUP(IF(staff[[#This Row],[Tenure]]>3,3%,2%)*staff[[#This Row],[Salary]],0) -> 1050 | K5: =_xlfn.XLOOKUP(staff[[#This Row],[Rating]],Analysis!$B$2:$B$6,Analysis!$C$2:$C$6) -> 3 | N5: Average Age | O5: =AVERAGE(staff[[#All],[Age]]) -> 30.42623 | P5: Median | Q5: =MEDIAN(staff[[#All],[Age]]) -> 30
A6: Waheeda Vasuman | B6: Male | C6: 43 | D6: Average | E6: 44558 | F6: Sales | G6: 36040 | H6: India | I6: =(TODAY()-staff[[#This Row],[Date Joined]])/365 -> 4.3123288 | J6: =ROUNDUP(IF(staff[[#This Row],[Tenure]]>3,3%,2%)*staff[[#This Row],[Salary]],0) -> 1082 | K6: =_xlfn.XLOOKUP(staff[[#This Row],[Rating]],Analysis!$B$2:$B$6,Analysis!$C$2:$C$6) -> 3 | N6: Average Tenure | O6: =AVERAGE(staff[Tenure]) -> 4.6547047
A7: Bili Sizey | B7: Male | C7: 43 | D7: Average | E7: 44620 | F7: Sales | G7: 36040 | H7: NZ | I7: =(TODAY()-staff[[#This Row],[Date Joined]])/365 -> 4.1424658 | J7: =ROUNDUP(IF(staff[[#This Row],[Tenure]]>3,3%,2%)*staff[[#This Row],[Salary]],0) -> 1082 | K7: =_xlfn.XLOOKUP(staff[[#This Row],[Rating]],Analysis!$B$2:$B$6,Analysis!$C$2:$C$6) -> 3 | N7: Female Ratio %
A8: Akbar Sorabhjee | B8: Male | C8: 21 | D8: Average | E8: 44042 | F8: Procurement | G8: 37920 | H8: India | I8: =(TODAY()-staff[[#This Row],[Date Joined]])/365 -> 5.7260274 | J8: =ROUNDUP(IF(staff[[#This Row],[Tenure]]>3,3%,2%)*staff[[#This Row],[Salary]],0) -> 1138 | K8: =_xlfn.XLOOKUP(staff[[#This Row],[Rating]],Analysis!$B$2:$B$6,Analysis!$C$2:$C$6) -> 3 | N8: Female Count | O8: =COUNTIFS(staff[Gender],"Female") -> 86
A9: Orton Livick | B9: Male | C9: 21 | D9: Average | E9: 44104 | F9: Procurement | G9: 37920 | H9: NZ | I9: =(TODAY()-staff[[#This Row],[Date Joined]])/365 -> 5.5561644 | J9: =ROUNDUP(IF(staff[[#This Row],[Tenure]]>3,3%,2%)*staff[[#This Row],[Salary]],0) -> 1138 | K9: =_xlfn.XLOOKUP(staff[[#This Row],[Rating]],Analysis!$B$2:$B$6,Analysis!$C$2:$C$6) -> 3 | N9: Female Ratio | O9: =O8/O3 -> 0.46994536
A10: Shobhana Samuel | B10: Male | C10: 35 | D10: Average | E10: 44666 | F10: Procurement | G10: 40400 | H10: India | I10: =(TODAY()-staff[[#This Row],[Date Joined]])/365 -> 4.0164384 | J10: =ROUNDUP(IF(staff[[#This Row],[Tenure]]>3,3%,2%)*staff[[#This Row],[Salary]],0) -> 1212 | K10: =_xlfn.XLOOKUP(staff[[#This Row],[Rating]],Analysis!$B$2:$B$6,Analysis!$C$2:$C$6) -> 3
A11: Archibald Filliskirk | B11: Male | C11: 35 | D11: Average | E11: 44727 | F11: Procurement | G11: 40400 | H11: NZ | I11: =(TODAY()-staff[[#This Row],[Date Joined]])/365 -> 3.8493151 | J11: =ROUNDUP(IF(staff[[#This Row],[Tenure]]>3,3%,2%)*staff[[#This Row],[Salary]],0) -> 1212 | K11: =_xlfn.XLOOKUP(staff[[#This Row],[Rating]],Analysis!$B$2:$B$6,Analysis!$C$2:$C$6) -> 3 | N11: Ration of >90,000$ | O11: =COUNTIFS(staff[Salary],">90000") -> 63
A12: Prerana Nishita | B12: Female | C12: 32 | D12: Average | E12: 44549 | F12: Procurement | G12: 41570 | H12: India | I12: =(TODAY()-staff[[#This Row],[Date Joined]])/365 -> 4.3369863 | J12: =ROUNDUP(IF(staff[[#This Row],[Tenure]]>3,3%,2%)*staff[[#This Row],[Salary]],0) -> 1248 | K12: =_xlfn.XLOOKUP(staff[[#This Row],[Rating]],Analysis!$B$2:$B$6,Analysis!$C$2:$C$6) -> 3 | N12: Ration = | O12: =O11/O3 -> 0.3442623
A13: Crissie Cordel | B13: Female | C13: 32 | D13: Average | E13: 44611 | F13: Procurement | G13: 41570 | H13: NZ | I13: =(TODAY()-staff[[#This Row],[Date Joined]])/365 -> 4.1671233 | J13: =ROUNDUP(IF(staff[[#This Row],[Tenure]]>3,3%,2%)*staff[[#This Row],[Salary]],0) -> 1248 | K13: =_xlfn.XLOOKUP(staff[[#This Row],[Rating]],Analysis!$B$2:$B$6,Analysis!$C$2:$C$6) -> 3
A14: Jagajeet Viraj | B14: Female | C14: 31 | D14: Average | E14: 44084 | F14: Website | G14: 41980 | H14: India | I14: =(TODAY()-staff[[#This Row],[Date Joined]])/365 -> 5.6109589 | J14: =ROUNDUP(IF(staff[[#This Row],[Tenure]]>3,3%,2%)*staff[[#This Row],[Salary]],0) -> 1260 | K14: =_xlfn.XLOOKUP(staff[[#This Row],[Rating]],Analysis!$B$2:$B$6,Analysis!$C$2:$C$6) -> 3
A15: Dotty Strutley | B15: Female | C15: 31 | D15: Average | E15: 44145 | F15: Website | G15: 41980 | H15: NZ | I15: =(TODAY()-staff[[#This Row],[Date Joined]])/365 -> 5.4438356 | J15: =ROUNDUP(IF(staff[[#This Row],[Tenure]]>3,3%,2%)*staff[[#This Row],[Salary]],0) -> 1260 | K15: =_xlfn.XLOOKUP(staff[[#This Row],[Rating]],Analysis!$B$2:$B$6,Analysis!$C$2:$C$6) -> 3
A16: Rupak Mehra | B16: Male | C16: 28 | D16: Very poor | E16: 44758 | F16: Sales | G16: 43510 | H16: India | I16: =(TODAY()-staff[[#This Row],[Date Joined]])/365 -> 3.7643836 | J16: =ROUNDUP(IF(staff[[#This Row],[Tenure]]>3,3%,2%)*staff[[#This Row],[Salary]],0) -> 1306 | K16: =_xlfn.XLOOKUP(staff[[#This Row],[Rating]],Analysis!$B$2:$B$6,Analysis!$C$2:$C$6) -> 1
A17: Drusy MacCombe | B17: Male | C17: 28 | D17: Very poor | E17: 44820 | F17: Sales | G17: 43510 | H17: NZ | I17: =(TODAY()-staff[[#This Row],[Date Joined]])/365 -> 3.5945205 | J17: =ROUNDUP(IF(staff[[#This Row],[Tenure]]>3,3%,2%)*staff[[#This Row],[Salary]],0) -> 1306 | K17: =_xlfn.XLOOKUP(staff[[#This Row],[Rating]],Analysis!$B$2:$B$6,Analysis!$C$2:$C$6) -> 1
A18: Yagna Sujeev | B18: Female | C18: 32 | D18: Above average | E18: 44293 | F18: Website | G18: 43840 | H18: India | I18: =(TODAY()-staff[[#This Row],[Date Joined]])/365 -> 5.0383562 | J18: =ROUNDUP(IF(staff[[#This Row],[Tenure]]>3,3%,2%)*staff[[#This Row],[Salary]],0) -> 1316 | K18: =_xlfn.XLOOKUP(staff[[#This Row],[Rating]],Analysis!$B$2:$B$6,Analysis!$C$2:$C$6) -> 4 | M18: 2
A19: Kassi Jonson | B19: Female | C19: 32 | D19: Above average | E19: 44354 | F19: Website | G19: 43840 | H19: NZ | I19: =(TODAY()-staff[[#This Row],[Date Joined]])/365 -> 4.8712329 | J19: =ROUNDUP(IF(staff[[#This Row],[Tenure]]>3,3%,2%)*staff[[#This Row],[Salary]],0) -> 1316 | K19: =_xlfn.XLOOKUP(staff[[#This Row],[Rating]],Analysis!$B$2:$B$6,Analysis!$C$2:$C$6) -> 4 | N19: Udyan Lanka
A20: Madhavdas Buhpathi | B20: Female | C20: 32 | D20: Average | E20: 44339 | F20: HR | G20: 45510 | H20: India | I20: =(TODAY()-staff[[#This Row],[Date Joined]])/365 -> 4.9123288 | J20: =ROUNDUP(IF(staff[[#This Row],[Tenure]]>3,3%,2%)*staff[[#This Row],[Salary]],0) -> 1366 | K20: =_xlfn.XLOOKUP(staff[[#This Row],[Rating]],Analysis!$B$2:$B$6,Analysis!$C$2:$C$6) -> 3
A21: Florinda Crace | B21: Female | C21: 32 | D21: Average | E21: 44400 | F21: HR | G21: 45510 | H21: NZ | I21: =(TODAY()-staff[[#This Row],[Date Joined]])/365 -> 4.7452055 | J21: =ROUNDUP(IF(staff[[#This Row],[Tenure]]>3,3%,2%)*staff[[#This Row],[Salary]],0) -> 1366 | K21: =_xlfn.XLOOKUP(staff[[#This Row],[Rating]],Analysis!$B$2:$B$6,Analysis!$C$2:$C$6) -> 3 | N21: XLOOKUP
A22: Shiuli Sapna | B22: Male | C22: 26 | D22: Average | E22: 44164 | F22: Procurement | G22: 47360 | H22: India | I22: =(TODAY()-staff[[#This Row],[Date Joined]])/365 -> 5.3917808 | J22: =ROUNDUP(IF(staff[[#This Row],[Tenure]]>3,3%,2%)*staff[[#This Row],[Salary]],0) -> 1421 | K22: =_xlfn.XLOOKUP(staff[[#This Row],[Rating]],Analysis!$B$2:$B$6,Analysis!$C$2:$C$6) -> 3
A23: Dell Molloy | B23: Male | C23: 26 | D23: Average | E23: 44225 | F23: Procurement | G23: 47360 | H23: NZ | I23: =(TODAY()-staff[[#This Row],[Date Joined]])/365 -> 5.2246575 | J23: =ROUNDUP(IF(staff[[#This Row],[Tenure]]>3,3%,2%)*staff[[#This Row],[Salary]],0) -> 1421 | K23: =_xlfn.XLOOKUP(staff[[#This Row],[Rating]],Analysis!$B$2:$B$6,Analysis!$C$2:$C$6) -> 3 | N23: {=_xlfn.XLOOKUP(N19,staff[Name],staff[[Gender]:[Tenure]])} -> Male | O23: 20 | P23: Average | Q23: 44683 | R23: Procurement | S23: 79570 | T23: India | U23: 3.969863
A24: Ardhendu Abhichandra Jayakar | B24: Male | C24: 28 | D24: Above average | E24: 43980 | F24: Finance | G24: 48170 | H24: India | I24: =(TODAY()-staff[[#This Row],[Date Joined]])/365 -> 5.8958904 | J24: =ROUNDUP(IF(staff[[#This Row],[Tenure]]>3,3%,2%)*staff[[#This Row],[Salary]],0) -> 1446 | K24: =_xlfn.XLOOKUP(staff[[#This Row],[Rating]],Analysis!$B$2:$B$6,Analysis!$C$2:$C$6) -> 4
A25: Jan Morforth | B25: Male | C25: 28 | D25: Above average | E25: 44041 | F25: Finance | G25: 48170 | H25: NZ | I25: =(TODAY()-staff[[#This Row],[Date Joined]])/365 -> 5.7287671 | J25: =ROUNDUP(IF(staff[[#This Row],[Tenure]]>3,3%,2%)*staff[[#This Row],[Salary]],0) -> 1446 | K25: =_xlfn.XLOOKUP(staff[[#This Row],[Rating]],Analysis!$B$2:$B$6,Analysis!$C$2:$C$6) -> 4 | N25: Gender | O25: {=TRANSPOSE(_xlfn.XLOOKUP(N19,staff[Name],staff[[Gender]:[Tenure]]))} -> Male
A26: Piyali Mahanthapa | B26: Male | C26: 33 | D26: Above average | E26: 44640 | F26: Procurement | G26: 48530 | H26: India | I26: =(TODAY()-staff[[#This Row],[Date Joined]])/365 -> 4.0876712 | J26: =ROUNDUP(IF(staff[[#This Row],[Tenure]]>3,3%,2%)*staff[[#This Row],[Salary]],0) -> 1456 | K26: =_xlfn.XLOOKUP(staff[[#This Row],[Rating]],Analysis!$B$2:$B$6,Analysis!$C$2:$C$6) -> 4 | N26: Age | O26: 20
A27: Erin Androsik | B27: Male | C27: 33 | D27: Above average | E27: 44701 | F27: Procurement | G27: 48530 | H27: NZ | I27: =(TODAY()-staff[[#This Row],[Date Joined]])/365 -> 3.9205479 | J27: =ROUNDUP(IF(staff[[#This Row],[Tenure]]>3,3%,2%)*staff[[#This Row],[Salary]],0) -> 1456 | K27: =_xlfn.XLOOKUP(staff[[#This Row],[Rating]],Analysis!$B$2:$B$6,Analysis!$C$2:$C$6) -> 4 | N27: Rating | O27: Average
A28: Amal Nimesh | B28: Male | C28: 31 | D28: Average | E28: 44450 | F28: Website | G28: 48950 | H28: India | I28: =(TODAY()-staff[[#This Row],[Date Joined]])/365 -> 4.6082192 | J28: =ROUNDUP(IF(staff[[#This Row],[Tenure]]>3,3%,2%)*staff[[#This Row],[Salary]],0) -> 1469 | K28: =_xlfn.XLOOKUP(staff[[#This Row],[Rating]],Analysis!$B$2:$B$6,Analysis!$C$2:$C$6) -> 3 | N28: Date Joined | O28: 44683
A29: Gunar Cockshoot | B29: Male | C29: 31 | D29: Average | E29: 44511 | F29: Website | G29: 48950 | H29: NZ | I29: =(TODAY()-staff[[#This Row],[Date Joined]])/365 -> 4.4410959 | J29: =ROUNDUP(IF(staff[[#This Row],[Tenure]]>3,3%,2%)*staff[[#This Row],[Salary]],0) -> 1469 | K29: =_xlfn.XLOOKUP(staff[[#This Row],[Rating]],Analysis!$B$2:$B$6,Analysis!$C$2:$C$6) -> 3 | N29: Department | O29: Procurement
A30: Vanmala Shriharsha | B30: Male | C30: 27 | D30: Average | E30: 44506 | F30: Finance | G30: 48980 | H30: India | I30: =(TODAY()-staff[[#This Row],[Date Joined]])/365 -> 4.4547945 | J30: =ROUNDUP(IF(staff[[#This Row],[Tenure]]>3,3%,2%)*staff[[#This Row],[Salary]],0) -> 1470 | K30: =_xlfn.XLOOKUP(staff[[#This Row],[Rating]],Analysis!$B$2:$B$6,Analysis!$C$2:$C$6) -> 3 | N30: Salary | O30: 79570
A31: Esmaria Denecamp | B31: Male | C31: 27 | D31: Average | E31: 44567 | F31: Finance | G31: 48980 | H31: NZ | I31: =(TODAY()-staff[[#This Row],[Date Joined]])/365 -> 4.2876712 | J31: =ROUNDUP(IF(staff[[#This Row],[Tenure]]>3,3%,2%)*staff[[#This Row],[Salary]],0) -> 1470 | K31: =_xlfn.XLOOKUP(staff[[#This Row],[Rating]],Analysis!$B$2:$B$6,Analysis!$C$2:$C$6) -> 3 | N31: Country | O31: India
A32: Daruka Ghazali | B32: Female | C32: 34 | D32: Poor | E32: 44660 | F32: Sales | G32: 49630 | H32: India | I32: =(TODAY()-staff[[#This Row],[Date Joined]])/365 -> 4.0328767 | J32: =ROUNDUP(IF(staff[[#This Row],[Tenure]]>3,3%,2%)*staff[[#This Row],[Salary]],0) -> 1489 | K32: =_xlfn.XLOOKUP(staff[[#This Row],[Rating]],Analysis!$B$2:$B$6,Analysis!$C$2:$C$6) -> 2 | N32: Tenure | O32: 3.969863
A33: Violante Courtonne | B33: Female | C33: 34 | D33: Poor | E33: 44721 | F33: Sales | G33: 49630 | H33: NZ | I33: =(TODAY()-staff[[#This Row],[Date Joined]])/365 -> 3.8657534 | J33: =ROUNDUP(IF(staff[[#This Row],[Tenure]]>3,3%,2%)*staff[[#This Row],[Salary]],0) -> 1489 | K33: =_xlfn.XLOOKUP(staff[[#This Row],[Rating]],Analysis!$B$2:$B$6,Analysis!$C$2:$C$6) -> 2
A34: Gumwant Veera | B34: Male | C34: 24 | D34: Poor | E34: 44375 | F34: Finance | G34: 52610 | H34: India | I34: =(TODAY()-staff[[#This Row],[Date Joined]])/365 -> 4.8136986 | J34: =ROUNDUP(IF(staff[[#This Row],[Tenure]]>3,3%,2%)*staff[[#This Row],[Salary]],0) -> 1579 | K34: =_xlfn.XLOOKUP(staff[[#This Row],[Rating]],Analysis!$B$2:$B$6,Analysis!$C$2:$C$6) -> 2
A35: Kaye Crocroft | B35: Male | C35: 24 | D35: Poor | E35: 44436 | F35: Finance | G35: 52610 | H35: NZ | I35: =(TODAY()-staff[[#This Row],[Date Joined]])/365 -> 4.6465753 | J35: =ROUNDUP(IF(staff[[#This Row],[Tenure]]>3,3%,2%)*staff[[#This Row],[Salary]],0) -> 1579 | K35: =_xlfn.XLOOKUP(staff[[#This Row],[Rating]],Analysis!$B$2:$B$6,Analysis!$C$2:$C$6) -> 2 | N35: VLOOKUP
A36: Anumati Shyamari Meherhomji | B36: Female | C36: 28 | D36: Average | E36: 44296 | F36: Sales | G36: 53240 | H36: India | I36: =(TODAY()-staff[[#This Row],[Date Joined]])/365 -> 5.030137 | J36: =ROUNDUP(IF(staff[[#This Row],[Tenure]]>3,3%,2%)*staff[[#This Row],[Salary]],0) -> 1598 | K36: =_xlfn.XLOOKUP(staff[[#This Row],[Rating]],Analysis!$B$2:$B$6,Analysis!$C$2:$C$6) -> 3
A37: Tatum Hush | B37: Female | C37: 28 | D37: Average | E37: 44357 | F37: Sales | G37: 53240 | H37: NZ | I37: =(TODAY()-staff[[#This Row],[Date Joined]])/365 -> 4.8630137 | J37: =ROUNDUP(IF(staff[[#This Row],[Tenure]]>3,3%,2%)*staff[[#This Row],[Salary]],0) -> 1598 | K37: =_xlfn.XLOOKUP(staff[[#This Row],[Rating]],Analysis!$B$2:$B$6,Analysis!$C$2:$C$6) -> 3
A38: Geena Raghavanpillai | B38: Male | C38: 32 | D38: Average | E38: 44403 | F38: Sales | G38: 53540 | H38: India | I38: =(TODAY()-staff[[#This Row],[Date Joined]])/365 -> 4.7369863 | J38: =ROUNDUP(IF(staff[[#This Row],[Tenure]]>3,3%,2%)*staff[[#This Row],[Salary]],0) -> 1607 | K38: =_xlfn.XLOOKUP(staff[[#This Row],[Rating]],Analysis!$B$2:$B$6,Analysis!$C$2:$C$6) -> 3
A39: Chitrasen Laul | B39: Male | C39: 26 | D39: Average | E39: 44350 | F39: Procurement | G39: 53540 | H39: India | I39: =(TODAY()-staff[[#This Row],[Date Joined]])/365 -> 4.8821918 | J39: =ROUNDUP(IF(staff[[#This Row],[Tenure]]>3,3%,2%)*staff[[#This Row],[Salary]],0) -> 1607 | K39: =_xlfn.XLOOKUP(staff[[#This Row],[Rating]],Analysis!$B$2:$B$6,Analysis!$C$2:$C$6) -> 3
A40: Hoyt D'Alesco | B40: Male | C40: 32 | D40: Average | E40: 44465 | F40: Sales | G40: 53540 | H40: NZ | I40: =(TODAY()-staff[[#This Row],[Date Joined]])/365 -> 4.5671233 | J40: =ROUNDUP(IF(staff[[#This Row],[Tenure]]>3,3%,2%)*staff[[#This Row],[Salary]],0) -> 1607 | K40: =_xlfn.XLOOKUP(staff[[#This Row],[Rating]],Analysis!$B$2:$B$6,Analysis!$C$2:$C$6) -> 3
...

Sheet Info Finder 2.0
B2: 3 | C2: Information Finder
B5: Department Name | C5: Website
B7: Number of People | C7: =COUNTIFS(staff[Department],C5) -> 54
B9: {=_xlfn._xlws.SORT(INDEX(_xlfn._xlws.FILTER(staff[],staff[Department]=C5),_xlfn.SEQUENCE(ROWS(_xlfn._xlws.FILTER(staff[],staff[Department]=C5))),{1,7,4}),2,-1)} -> Heer Pennathur | C9: 118840 | D9: Average
B10: Tawnya Tickel | C10: 118840 | D10: Average
B11: Ramnath Ravuri | C11: 114870 | D11: Average
B12: Wilone O'Kielt | C12: 114870 | D12: Average
B13: Deepali Charan | C13: 112650 | D13: Average
B14: Mollie Hanway | C14: 112650 | D14: Average
B15: Narois Motiwala | C15: 112110 | D15: Poor
B16: Bev Lashley | C16: 112110 | D16: Poor
B17: Hridaynath Tendulkar | C17: 107700 | D17: Average
B18: Kaine Padly | C18: 107700 | D18: Average
B19: Manjusri Ruchi | C19: 104410 | D19: Average
B20: Caro Chappel | C20: 104410 | D20: Average
B21: Amlankusum Rajabhushan | C21: 100420 | D21: Average
... B62: Gretchen Callow | C62: 33920 | D62: Average

Sheet Male vs Female
B2: 4 | C2: Male Vs Female
C6: Column Labels
B7: Values | C7: Female | D7: Male
B8: Count of Name | C8: 86 | D8: 89
B9: Average of Age | C9: 31.406977 | D9: 29.393258
B10: Average of Salary | C10: 78284.186 | D10: 74915.169
B11: Average of Tenure | C11: 4.6572794 | D11: 4.6481761

Sheet Bonus calculation
B2: 5 | C2: Bonus Calculation
B6: Row Labels | C6: Sum of Bonus
B7: Benny Karolovsky | C7: 3464
B8: Sahila Chandrasekhar | C8: 3464
B9: Roddy Speechley | C9: 3478
B10: Sarayu Ragunathan | C10: 3478
B11: Kaishori Harathi Kateel | C11: 3543
B12: Valentia Etteridge | C12: 3543
B13: Heer Pennathur | C13: 3566
B14: Tawnya Tickel | C14: 3566
B15: Anjushri Chandiramani | C15: 3574
B16: Ewart Laphorn | C16: 3574
B17: Grand Total | C17: 35250

Sheet Salary Spread

Sheet Salary vs Rating
B3: Row Labels | C3: Count of Name | D3: Average of Salary
B4: Exceptional | C4: 4 | D4: 92080
B5: Above average | C5: 20 | D5: 75933
B6: Average | C6: 137 | D6: 76798.759
B7: Poor | C7: 16 | D7: 78115
B8: Very poor | C8: 6 | D8: 77423.333
B9: Grand Total | C9: 183 | D9: 77173.716

Sheet Analysis
B2: Exceptional | C2: 5
B3: Above average | C3: 4
B4: Average | C4: 3
B5: Poor | C5: 2
B6: Very poor | C6: 1

Sheet Employee Trend
B2: Row Labels | C2: Count of Name
B3: 2020 | Q3: Month | R3: Head Count | S3: Running Total
B4: May | C4: 3 | P4: {=_xlfn.SEQUENCE(36)} -> 1 | Q4: {=EDATE(DATE(2020,4,1),_xlfn.ANCHORARRAY(P4)+0)} -> 43952 | R4: =COUNTIFS(staff[Date Joined],">="&Q4,staff[Date Joined],"<="&EOMONTH(Q4,0)) -> 3 | S4: =SUM($R$4:R4) -> 3
B5: Jun | C5: 4 | P5: 2 | Q5: 43983 | R5: =COUNTIFS(staff[Date Joined],">="&Q5,staff[Date Joined],"<="&EOMONTH(Q5,0)) -> 1 | S5: =SUM($R$4:R5) -> 4
B6: Jul | C6: 9 | P6: 3 | Q6: 44013 | R6: =COUNTIFS(staff[Date Joined],">="&Q6,staff[Date Joined],"<="&EOMONTH(Q6,0)) -> 5 | S6: =SUM($R$4:R6) -> 9
B7: Aug | C7: 12 | P7: 4 | Q7: 44044 | R7: =COUNTIFS(staff[Date Joined],">="&Q7,staff[Date Joined],"<="&EOMONTH(Q7,0)) -> 3 | S7: =SUM($R$4:R7) -> 12
B8: Sep | C8: 18 | P8: 5 | Q8: 44075 | R8: =COUNTIFS(staff[Date Joined],">="&Q8,staff[Date Joined],"<="&EOMONTH(Q8,0)) -> 6 | S8: =SUM($R$4:R8) -> 18
B9: Oct | C9: 24 | P9: 6 | Q9: 44105 | R9: =COUNTIFS(staff[Date Joined],">="&Q9,staff[Date Joined],"<="&EOMONTH(Q9,0)) -> 6 | S9: =SUM($R$4:R9) -> 24
B10: Nov | C10: 30 | P10: 7 | Q10: 44136 | R10: =COUNTIFS(staff[Date Joined],">="&Q10,staff[Date Joined],"<="&EOMONTH(Q10,0)) -> 6 | S10: =SUM($R$4:R10) -> 30
B11: Dec | C11: 37 | P11: 8 | Q11: 44166 | R11: =COUNTIFS(staff[Date Joined],">="&Q11,staff[Date Joined],"<="&EOMONTH(Q11,0)) -> 7 | S11: =SUM($R$4:R11) -> 37
B12: 2021 | P12: 9 | Q12: 44197 | R12: =COUNTIFS(staff[Date Joined],">="&Q12,staff[Date Joined],"<="&EOMONTH(Q12,0)) -> 6 | S12: =SUM($R$4:R12) -> 43
B13: Jan | C13: 6 | P13: 10 | Q13: 44228 | R13: =COUNTIFS(staff[Date Joined],">="&Q13,staff[Date Joined],"<="&EOMONTH(Q13,0)) -> 4 | S13: =SUM($R$4:R13) -> 47
B14: Feb | C14: 10 | P14: 11 | Q14: 44256 | R14: =COUNTIFS(staff[Date Joined],">="&Q14,staff[Date Joined],"<="&EOMONTH(Q14,0)) -> 9 | S14: =SUM($R$4:R14) -> 56
B15: Mar | C15: 19 | P15: 12 | Q15: 44287 | R15: =COUNTIFS(staff[Date Joined],">="&Q15,staff[Date Joined],"<="&EOMONTH(Q15,0)) -> 5 | S15: =SUM($R$4:R15) -> 61
B16: Apr | C16: 24 | P16: 13 | Q16: 44317 | R16: =COUNTIFS(staff[Date Joined],">="&Q16,staff[Date Joined],"<="&EOMONTH(Q16,0)) -> 10 | S16: =SUM($R$4:R16) -> 71
B17: May | C17: 34 | P17: 14 | Q17: 44348 | R17: =COUNTIFS(staff[Date Joined],">="&Q17,staff[Date Joined],"<="&EOMONTH(Q17,0)) -> 6 | S17: =SUM($R$4:R17) -> 77
B18: Jun | C18: 40 | P18: 15 | Q18: 44378 | R18: =COUNTIFS(staff[Date Joined],">="&Q18,staff[Date Joined],"<="&EOMONTH(Q18,0)) -> 13 | S18: =SUM($R$4:R18) -> 90
B19: Jul | C19: 53 | P19: 16 | Q19: 44409 | R19: =COUNTIFS(staff[Date Joined],">="&Q19,staff[Date Joined],"<="&EOMONTH(Q19,0)) -> 4 | S19: =SUM($R$4:R19) -> 94
B20: Aug | C20: 57 | P20: 17 | Q20: 44440 | R20: =COUNTIFS(staff[Date Joined],">="&Q20,staff[Date Joined],"<="&EOMONTH(Q20,0)) -> 11 | S20: =SUM($R$4:R20) -> 105
B21: Sep | C21: 68 | P21: 18 | Q21: 44470 | R21: =COUNTIFS(staff[Date Joined],">="&Q21,staff[Date Joined],"<="&EOMONTH(Q21,0)) -> 3 | S21: =SUM($R$4:R21) -> 108
B22: Oct | C22: 71 | P22: 19 | Q22: 44501 | R22: =COUNTIFS(staff[Date Joined],">="&Q22,staff[Date Joined],"<="&EOMONTH(Q22,0)) -> 4 | S22: =SUM($R$4:R22) -> 112
B23: Nov | C23: 75 | P23: 20 | Q23: 44531 | R23: =COUNTIFS(staff[Date Joined],">="&Q23,staff[Date Joined],"<="&EOMONTH(Q23,0)) -> 7 | S23: =SUM($R$4:R23) -> 119
B24: Dec | C24: 82 | P24: 21 | Q24: 44562 | R24: =COUNTIFS(staff[Date Joined],">="&Q24,staff[Date Joined],"<="&EOMONTH(Q24,0)) -> 3 | S24: =SUM($R$4:R24) -> 122
B25: 2022 | P25: 22 | Q25: 44593 | R25: =COUNTIFS(staff[Date Joined],">="&Q25,staff[Date Joined],"<="&EOMONTH(Q25,0)) -> 10 | S25: =SUM($R$4:R25) -> 132
B26: Jan | C26: 3 | P26: 23 | Q26: 44621 | R26: =COUNTIFS(staff[Date Joined],">="&Q26,staff[Date Joined],"<="&EOMONTH(Q26,0)) -> 9 | S26: =SUM($R$4:R26) -> 141
B27: Feb | C27: 13 | P27: 24 | Q27: 44652 | R27: =COUNTIFS(staff[Date Joined],">="&Q27,staff[Date Joined],"<="&EOMONTH(Q27,0)) -> 9 | S27: =SUM($R$4:R27) -> 150
B28: Mar | C28: 22 | P28: 25 | Q28: 44682 | R28: =COUNTIFS(staff[Date Joined],">="&Q28,staff[Date Joined],"<="&EOMONTH(Q28,0)) -> 9 | S28: =SUM($R$4:R28) -> 159
B29: Apr | C29: 31 | P29: 26 | Q29: 44713 | R29: =COUNTIFS(staff[Date Joined],">="&Q29,staff[Date Joined],"<="&EOMONTH(Q29,0)) -> 7 | S29: =SUM($R$4:R29) -> 166
B30: May | C30: 40 | P30: 27 | Q30: 44743 | R30: =COUNTIFS(staff[Date Joined],">="&Q30,staff[Date Joined],"<="&EOMONTH(Q30,0)) -> 5 | S30: =SUM($R$4:R30) -> 171
B31: Jun | C31: 47 | P31: 28 | Q31: 44774 | R31: =COUNTIFS(staff[Date Joined],">="&Q31,staff[Date Joined],"<="&EOMONTH(Q31,0)) -> 5 | S31: =SUM($R$4:R31) -> 176
B32: Jul | C32: 52 | P32: 29 | Q32: 44805 | R32: =COUNTIFS(staff[Date Joined],">="&Q32,staff[Date Joined],"<="&EOMONTH(Q32,0)) -> 2 | S32: =SUM($R$4:R32) -> 178
B33: Aug | C33: 57 | P33: 30 | Q33: 44835 | R33: =COUNTIFS(staff[Date Joined],">="&Q33,staff[Date Joined],"<="&EOMONTH(Q33,0)) -> 3 | S33: =SUM($R$4:R33) -> 181
B34: Sep | C34: 59 | P34: 31 | Q34: 44866 | R34: =COUNTIFS(staff[Date Joined],">="&Q34,staff[Date Joined],"<="&EOMONTH(Q34,0)) -> 0 | S34: =SUM($R$4:R34) -> 181
B35: Oct | C35: 62 | P35: 32 | Q35: 44896 | R35: =COUNTIFS(staff[Date Joined],">="&Q35,staff[Date Joined],"<="&EOMONTH(Q35,0)) -> 0 | S35: =SUM($R$4:R35) -> 181
B36: 2023 | P36: 33 | Q36: 44927 | R36: =COUNTIFS(staff[Date Joined],">="&Q36,staff[Date Joined],"<="&EOMONTH(Q36,0)) -> 0 | S36: =SUM($R$4:R36) -> 181
B37: Feb | C37: 1 | P37: 34 | Q37: 44958 | R37: =COUNTIFS(staff[Date Joined],">="&Q37,staff[Date Joined],"<="&EOMONTH(Q37,0)) -> 1 | S37: =SUM($R$4:R37) -> 182
B38: Apr | C38: 2 | P38: 35 | Q38: 44986 | R38: =COUNTIFS(staff[Date Joined],">="&Q38,staff[Date Joined],"<="&EOMONTH(Q38,0)) -> 0 | S38: =SUM($R$4:R38) -> 182
B39: Grand Total | P39: 36 | Q39: 45017 | R39: =COUNTIFS(staff[Date Joined],">="&Q39,staff[Date Joined],"<="&EOMONTH(Q39,0)) -> 1 | S39: =SUM($R$4:R39) -> 183

Sheet Final Report Card
C2: New Zealand | J2: India
C3: =COUNTIFS(staff[Country],"NZ") -> 91 | E3: =COUNTIFS(staff[Country],"NZ",staff[Gender],"Female")/C3 -> 0.47252747 | G3: =AVERAGEIFS(staff[Salary],staff[Country],"NZ") -> 76978.791 | J3: =COUNTIFS(staff[Country],"India") -> 92 | L3: =COUNTIFS(staff[Country],"India",staff[Gender],"Female")/J3 -> 0.4673913 | N3: =AVERAGEIFS(staff[Salary],staff[Country],"India") -> 77366.522
C6: Head Count by Department

Sheet Processed Data
B1: Country | C1: India | F1: Country | G1: NZ
B3: Row Labels | C3: Count of Name | F3: Row Labels | G3: Count of Name
B4: Procurement | C4: 28 | F4: Website | G4: 27
B5: Website | C5: 27 | F5: Procurement | G5: 27
B6: Finance | C6: 19 | F6: Finance | G6: 19
B7: Sales | C7: 14 | F7: Sales | G7: 14
B8: HR | C8: 4 | F8: HR | G8: 4
B9: Grand Total | C9: 92 | F9: Grand Total | G9: 91
